Workbook

Sheet Інструкція
A1: Інструкція користування файлом
A2: Графіки вивезення ТПВ — КП «Послуга», Прилуцька міська рада
A4: 1. Структура файлу
A5: Аркуш | B5: Призначення | C5: Чи можна редагувати
A6: Інструкція | B6: Цей аркуш — опис структури та правил роботи. | C6: —
A7: Зміст | B7: Перелік аркушів із коротким описом. | C7: Так
A8: Зведена_по_адресах | B8: ГОЛОВНА таблиця: усі адреси × дні тижня з часом вивозу, кількість вивозів, маршрут, авто, координати. | C8: Ні — формули
A9: Зведена_детальна | B9: Перелік усіх 1009 зупинок окремими рядками (вулиця, будинок, день, час, маршрут, авто, лист-джерело). | C9: Ні — знімок даних
A10: Дані_зв'язок | B10: СЛУЖБОВИЙ. Посилання формулами на кожен рядок вихідних графіків. Проміжна ланка між джерелом і зведеною. | C10: Ні — не чіпати
A11: Геокодування | B11: Результат геокодування адрес (широта/довгота + формалізована адреса від сервісу). | C11: Так — можна доповнювати
A12: Координати майданчиків | B12: 61 контейнерний майданчик і сміттєприймальний пункт із точними координатами. | C12: Так
A13: М5_… , М1_… та інші 9 аркушів | B13: ПЕРВИННІ ДАНІ — графіки з відсканованих документів. Джерело для всіх розрахунків. | C13: Так — тут вносяться зміни
A15: 2. Як оновлюються дані
A16: Ланцюг: | B16: Вихідні аркуші маршрутів → Дані_зв'язок → Зведена_по_адресах
B17: Змінили час або назву вулиці у вихідному аркуші — зведена оновиться САМА, перераховувати нічого не треба.
A18: ВАЖЛИВО: | B18: Якщо у вихідному графіку з'явилася НОВА адреса (якої раніше не було) — вона НЕ додасться автоматично.
B19: Список адрес у службовій колонці O аркуша «Зведена_по_адресах» — статичний. Нову адресу треба дописати туди у форматі: вулиця|будинок
B20: Приклад: вул. Київська|140 (якщо будинку немає — просто: вул. Київська| )
A22: 3. Легенда кольорів на аркуші «Зведена_по_адресах»
A23: Зелена заливка клітинки дня | B23: Є вивезення ТПВ цього дня. У клітинці — час (кілька значень через кому = кілька вивозів). | C23: зразок
A24: Оранжева заливка + «×» | B24: Вивезення великогабаритних відходів (ВГВ). Час у первинному графіку не вказано. | C24: зразок
A25: Синя заливка адреси | B25: На цій адресі є контейнерний майданчик. Координати взято з аркуша «Координати майданчиків». | C25: зразок
A26: Червоний текст адреси | B26: Вивезення лише 1 раз на тиждень. | C26: зразок
A27: Зелений колір цифр/тексту | B27: Значення підтягується формулою з іншого аркуша (не вводити вручну). | C27: зразок
A29: 4. Колонки аркуша «Зведена_по_адресах» (колонка → що містить → джерело)
A30: A | B30: Назва вулиці | C30: Формула — з колонки O
A31: B | B31: Будинок / об'єкт | C31: Формула — з колонки O
A32: C–I | B32: Понеділок … Неділя | C32: Формула — час вивозу з «Дані_зв'язок»
A33: J | B33: Вивозів/тиждень | C33: Формула — рахує КОЖЕН час, а не дні (2 часи в одному дні = 2 вивози)
A34: K | B34: Маршрут(и) | C34: Формула — перелік маршрутів без повторів
A35: L | B35: Автомобіль(і) | C35: Формула — перелік авто без повторів
A36: M | B36: Контейнери | C36: Формула — максимальна кількість по адресі
A37: O | B37: Ключ (службова) | C37: СТАТИЧНО. Формат: вулиця|будинок. Керує всім рядком — якщо порожньо, рядок пустий.
A38: P | B38: Номер для геокоду | C38: Формула — найменший номер із переліку («2,10 24» → 2)
A39: Q | B39: Повна адреса для запиту | C39: Формула — рядок для геокодера
A40: R, S | B40: Широта / Довгота | C40: Формула — спершу з «Координати майданчиків», інакше з «Геокодування»
A41: T | B41: Майданчик | C41: СТАТИЧНО. Назва майданчика. Наявність значення = синя заливка адреси.
A43: 5. Важливі застереження
A44: Порожні координати | B44: Заповнено 199 із 464 адрес. Порожньо там, де геокодер не знайшов точну адресу (повернув центр міста) або дав хибну локацію (інше місто). Вигаданих координат у файлі НЕМА.
A45: Майданчики | B45: Зіставлено 38 із 61. Решту 23 не зіставлено, бо у графіках вивозу немає таких адрес (напр. Вокзальна 10 і 46 — у графіку є 3, 12, 29, 35).
...

Sheet Зміст
A1: Графіки вивезення ТПВ КП "Послуга" — Прилуцька міська рада
A2: Джерело: 9 сканованих графіків (SCAN0584-SCAN0592). Кожен лист відповідає одному скану.
A4: № | B4: Лист | C4: Опис
A5: 1 | B5: М5_МАЗ4381_0592 | C5: Графік вивезення ТПВ (побутові відходи) — Маршрут №5, автомобіль МАЗ 4381, реєстр. №СВ 81-71 ВК
A6: 2 | B6: М1_КАМАЗ55111_0591 | C6: Графік вивезення ТПВ — Маршрут №1, автомобіль КАМАЗ 55111, реєстр. №СВ 50-33 АР
A7: 3 | B7: М3-4_ГАЗ3309_0590 | C7: Графік вивезення ТПВ — Маршрут №3 і №4, автомобіль ГАЗ 3309, реєстр. №СВ 17-85 ВН
A8: 4 | B8: М2_ВГВ_РеноЛендер_0589 | C8: Графік вивезення великогабаритних побутових відходів — Маршрут №2, автомобіль Рено Лендер, реєстр. №СВ 52-62 СА
A9: 5 | B9: М2_АТ4021-1120_0588 | C9: Графік вивезення ТПВ — Маршрут №2, автомобіль АТ 4021/1120, реєстр. №СВ 64-11 ЕТ
A10: 6 | B10: М3_МАЗ4371_0587 | C10: Графік вивезення ТПВ — Маршрут №3, автомобіль МАЗ-4371, реєстр. №СВ 53-06 СА
A11: 7 | B11: М6_АТ4021_0586 | C11: Графік вивезення ТПВ — Маршрут №6, автомобіль АТ 4021, реєстр. №СВ 33-16 ЕО*
A12: 8 | B12: М1-2_АТ4021-1120_0585 | C12: Графік вивезення ТПВ — Маршрут №1 і №2, автомобіль АТ-4021/1120, реєстр. №СВ 14-65 ЕО
A13: 9 | B13: М4_АТ4042ROD_0584 | C13: Графік вивезення ТПВ — Маршрут №4, автомобіль АТ 40-42/ROD21003, реєстр. №СВ 33-15 ЕО
A15: Зведені таблиці
A16: 1 | B16: Зведена_по_адресах | C16: Зведена таблиця (на формулах): унікальні адреси × дні тижня з часом вивозу, вивозів/тиждень, маршрут, автомобіль. Оновлюється автоматично.
A17: 2 | B17: Зведена_детальна | C17: Детальний перелік усіх 1009 зупинок: вулиця, будинок, день, час, маршрут, авто, контейнери, лист-джерело
A18: 3 | B18: Дані_зв'язок | C18: Службовий аркуш: формульні посилання на всі 1009 рядків вихідних графіків. Ланцюг: вихідні аркуші → Дані_зв'язок → Зведена_по_адресах.
A19: 4 | B19: Геокодування | C19: Результат геокодування адрес: широта, довгота, формалізована адреса від сервісу
A20: 5 | B20: Координати майданчиків | C20: 61 контейнерний майданчик і сміттєприймальний пункт із точними координатами (єдина таблиця)
A22: Початок роботи
A23: → | B23: Інструкція | C23: ПОЧНІТЬ ЗВІДСИ: структура файлу, як оновлюються дані, легенда кольорів, опис колонок, застереження

Sheet Дані_зв'язок
A1: Проміжний аркуш: посилання на вихідні графіки. Не редагувати вручну — усі значення тягнуться формулами.
A3: Вулиця | B3: Будинок | C3: День тижня | D3: Час | E3: Маршрут | F3: Автомобіль | G3: Реєстр. № | H3: Контейнери | J3: Ключ (вулиця|будинок) | K3: Час (число) | L3: Маршрут 1-й раз | M3: Авто 1-й раз
A4: =IFERROR(М5_МАЗ4381_0592!B187,"") -> 1 в'їзд Вишневий | B4: =IFERROR(IF(М5_МАЗ4381_0592!C187="","",TEXT(М5_МАЗ4381_0592!C187,"General")),"") | C4: ="П'ятниця" -> П'ятниця | D4: =IFERROR(TEXT(М5_МАЗ4381_0592!D187,"h:mm"),"") -> 13:00 | E4: ="№5" -> №5 | F4: ="МАЗ 4381" -> МАЗ 4381 | G4: ="СВ 81-71 ВК" -> СВ 81-71 ВК | J4: =IF(A4="","",A4&"|"&B4) -> 1 в'їзд Вишневий| | K4: =IFERROR(IF(D4="","",IF(D4="×",9.99,TIMEVALUE(D4))),9.99) -> 0.54166667 | L4: =IF($A4="","",IF(COUNTIFS($J$4:$J4,$J4,$E$4:$E4,$E4)=1,$E4,"")) -> №5 | M4: =IF($A4="","",IF(COUNTIFS($J$4:$J4,$J4,$F$4:$F4,$F4)=1,$F4,"")) -> МАЗ 4381
A5: =IFERROR(М5_МАЗ4381_0592!B128,"") -> 1 пров. Європейський | B5: =IFERROR(IF(М5_МАЗ4381_0592!C128="","",TEXT(М5_МАЗ4381_0592!C128,"General")),"") | C5: ="Четвер" -> Четвер | D5: =IFERROR(TEXT(М5_МАЗ4381_0592!D128,"h:mm"),"") -> 9:00 | E5: ="№5" -> №5 | F5: ="МАЗ 4381" -> МАЗ 4381 | G5: ="СВ 81-71 ВК" -> СВ 81-71 ВК | J5: =IF(A5="","",A5&"|"&B5) -> 1 пров. Європейський| | K5: =IFERROR(IF(D5="","",IF(D5="×",9.99,TIMEVALUE(D5))),9.99) -> 0.375 | L5: =IF($A5="","",IF(COUNTIFS($J$4:$J5,$J5,$E$4:$E5,$E5)=1,$E5,"")) -> №5 | M5: =IF($A5="","",IF(COUNTIFS($J$4:$J5,$J5,$F$4:$F5,$F5)=1,$F5,"")) -> МАЗ 4381
A6: =IFERROR(М5_МАЗ4381_0592!B63,"") -> 1 пров. І. Сірка | B6: =IFERROR(IF(М5_МАЗ4381_0592!C63="","",TEXT(М5_МАЗ4381_0592!C63,"General")),"") | C6: ="Вівторок" -> Вівторок | D6: =IFERROR(TEXT(М5_МАЗ4381_0592!D63,"h:mm"),"") -> 12:20 | E6: ="№5" -> №5 | F6: ="МАЗ 4381" -> МАЗ 4381 | G6: ="СВ 81-71 ВК" -> СВ 81-71 ВК | J6: =IF(A6="","",A6&"|"&B6) -> 1 пров. І. Сірка| | K6: =IFERROR(IF(D6="","",IF(D6="×",9.99,TIMEVALUE(D6))),9.99) -> 0.51388889 | L6: =IF($A6="","",IF(COUNTIFS($J$4:$J6,$J6,$E$4:$E6,$E6)=1,$E6,"")) -> №5 | M6: =IF($A6="","",IF(COUNTIFS($J$4:$J6,$J6,$F$4:$F6,$F6)=1,$F6,"")) -> МАЗ 4381
A7: =IFERROR(М5_МАЗ4381_0592!B96,"") -> 1 пров. Андріївський | B7: =IFERROR(IF(М5_МАЗ4381_0592!C96="","",TEXT(М5_МАЗ4381_0592!C96,"General")),"") | C7: ="Середа" -> Середа | D7: =IFERROR(TEXT(М5_МАЗ4381_0592!D96,"h:mm"),"") -> 10:40 | E7: ="№5" -> №5 | F7: ="МАЗ 4381" -> МАЗ 4381 | G7: ="СВ 81-71 ВК" -> СВ 81-71 ВК | J7: =IF(A7="","",A7&"|"&B7) -> 1 пров. Андріївський| | K7: =IFERROR(IF(D7="","",IF(D7="×",9.99,TIMEVALUE(D7))),9.99) -> 0.44444444 | L7: =IF($A7="","",IF(COUNTIFS($J$4:$J7,$J7,$E$4:$E7,$E7)=1,$E7,"")) -> №5 | M7: =IF($A7="","",IF(COUNTIFS($J$4:$J7,$J7,$F$4:$F7,$F7)=1,$F7,"")) -> МАЗ 4381
A8: =IFERROR(М5_МАЗ4381_0592!B141,"") -> 1 пров. В. Стуса | B8: =IFERROR(IF(М5_МАЗ4381_0592!C141="","",TEXT(М5_МАЗ4381_0592!C141,"General")),"") | C8: ="Четвер" -> Четвер | D8: =IFERROR(TEXT(М5_МАЗ4381_0592!D141,"h:mm"),"") -> 12:45 | E8: ="№5" -> №5 | F8: ="МАЗ 4381" -> МАЗ 4381 | G8: ="СВ 81-71 ВК" -> СВ 81-71 ВК | J8: =IF(A8="","",A8&"|"&B8) -> 1 пров. В. Стуса| | K8: =IFERROR(IF(D8="","",IF(D8="×",9.99,TIMEVALUE(D8))),9.99) -> 0.53125 | L8: =IF($A8="","",IF(COUNTIFS($J$4:$J8,$J8,$E$4:$E8,$E8)=1,$E8,"")) -> №5 | M8: =IF($A8="","",IF(COUNTIFS($J$4:$J8,$J8,$F$4:$F8,$F8)=1,$F8,"")) -> МАЗ 4381
A9: =IFERROR(М6_АТ4021_0586!B169,"") -> 1 пров. Героїв Чорнобиля | B9: =IFERROR(IF(М6_АТ4021_0586!C169="","",TEXT(М6_АТ4021_0586!C169,"General")),"") -> 2,10 24 | C9: ="П'ятниця" -> П'ятниця | D9: =IFERROR(TEXT(М6_АТ4021_0586!D169,"h:mm"),"") -> 10:45 | E9: ="№6" -> №6 | F9: ="АТ 4021" -> АТ 4021 | G9: ="СВ 33-16 ЕО" -> СВ 33-16 ЕО | J9: =IF(A9="","",A9&"|"&B9) -> 1 пров. Героїв Чорнобиля|2,10 24 | K9: =IFERROR(IF(D9="","",IF(D9="×",9.99,TIMEVALUE(D9))),9.99) -> 0.44791667 | L9: =IF($A9="","",IF(COUNTIFS($J$4:$J9,$J9,$E$4:$E9,$E9)=1,$E9,"")) -> №6 | M9: =IF($A9="","",IF(COUNTIFS($J$4:$J9,$J9,$F$4:$F9,$F9)=1,$F9,"")) -> АТ 4021
A10: =IFERROR(М6_АТ4021_0586!B129,"") -> 1 пров. Замостянський | B10: =IFERROR(IF(М6_АТ4021_0586!C129="","",TEXT(М6_АТ4021_0586!C129,"General")),"") -> 36,42 54 | C10: ="Четвер" -> Четвер | D10: =IFERROR(TEXT(М6_АТ4021_0586!D129,"h:mm"),"") -> 9:55 | E10: ="№6" -> №6 | F10: ="АТ 4021" -> АТ 4021 | G10: ="СВ 33-16 ЕО" -> СВ 33-16 ЕО | J10: =IF(A10="","",A10&"|"&B10) -> 1 пров. Замостянський|36,42 54 | K10: =IFERROR(IF(D10="","",IF(D10="×",9.99,TIMEVALUE(D10))),9.99) -> 0.41319444 | L10: =IF($A10="","",IF(COUNTIFS($J$4:$J10,$J10,$E$4:$E10,$E10)=1,$E10,"")) -> №6 | M10: =IF($A10="","",IF(COUNTIFS($J$4:$J10,$J10,$F$4:$F10,$F10)=1,$F10,"")) -> АТ 4021
A11: =IFERROR(М5_МАЗ4381_0592!B27,"") -> 1 пров. Зелений | B11: =IFERROR(IF(М5_МАЗ4381_0592!C27="","",TEXT(М5_МАЗ4381_0592!C27,"General")),"") | C11: ="Понеділок" -> Понеділок | D11: =IFERROR(TEXT(М5_МАЗ4381_0592!D27,"h:mm"),"") -> 11:45 | E11: ="№5" -> №5 | F11: ="МАЗ 4381" -> МАЗ 4381 | G11: ="СВ 81-71 ВК" -> СВ 81-71 ВК | J11: =IF(A11="","",A11&"|"&B11) -> 1 пров. Зелений| | K11: =IFERROR(IF(D11="","",IF(D11="×",9.99,TIMEVALUE(D11))),9.99) -> 0.48958333 | L11: =IF($A11="","",IF(COUNTIFS($J$4:$J11,$J11,$E$4:$E11,$E11)=1,$E11,"")) -> №5 | M11: =IF($A11="","",IF(COUNTIFS($J$4:$J11,$J11,$F$4:$F11,$F11)=1,$F11,"")) -> МАЗ 4381
A12: =IFERROR(М5_МАЗ4381_0592!B161,"") -> 1 пров. Змагання | B12: =IFERROR(IF(М5_МАЗ4381_0592!C161="","",TEXT(М5_МАЗ4381_0592!C161,"General")),"") | C12: ="П'ятниця" -> П'ятниця | D12: =IFERROR(TEXT(М5_МАЗ4381_0592!D161,"h:mm"),"") -> 7:25 | E12: ="№5" -> №5 | F12: ="МАЗ 4381" -> МАЗ 4381 | G12: ="СВ 81-71 ВК" -> СВ 81-71 ВК | J12: =IF(A12="","",A12&"|"&B12) -> 1 пров. Змагання| | K12: =IFERROR(IF(D12="","",IF(D12="×",9.99,TIMEVALUE(D12))),9.99) -> 0.30902778 | L12: =IF($A12="","",IF(COUNTIFS($J$4:$J12,$J12,$E$4:$E12,$E12)=1,$E12,"")) -> №5 | M12: =IF($A12="","",IF(COUNTIFS($J$4:$J12,$J12,$F$4:$F12,$F12)=1,$F12,"")) -> МАЗ 4381
A13: =IFERROR(М5_МАЗ4381_0592!B179,"") -> 1 пров. Колгоспний | B13: =IFERROR(IF(М5_МАЗ4381_0592!C179="","",TEXT(М5_МАЗ4381_0592!C179,"General")),"") | C13: ="П'ятниця" -> П'ятниця | D13: =IFERROR(TEXT(М5_МАЗ4381_0592!D179,"h:mm"),"") -> 11:05 | E13: ="№5" -> №5 | F13: ="МАЗ 4381" -> МАЗ 4381 | G13: ="СВ 81-71 ВК" -> СВ 81-71 ВК | J13: =IF(A13="","",A13&"|"&B13) -> 1 пров. Колгоспний| | K13: =IFERROR(IF(D13="","",IF(D13="×",9.99,TIMEVALUE(D13))),9.99) -> 0.46180556 | L13: =IF($A13="","",IF(COUNTIFS($J$4:$J13,$J13,$E$4:$E13,$E13)=1,$E13,"")) -> №5 | M13: =IF($A13="","",IF(COUNTIFS($J$4:$J13,$J13,$F$4:$F13,$F13)=1,$F13,"")) -> МАЗ 4381
A14: =IFERROR(М6_АТ4021_0586!B29,"") -> 1 пров. Межовий | B14: =IFERROR(IF(М6_АТ4021_0586!C29="","",TEXT(М6_АТ4021_0586!C29,"General")),"") -> 1,2 5,8 | C14: ="Понеділок" -> Понеділок | D14: =IFERROR(TEXT(М6_АТ4021_0586!D29,"h:mm"),"") -> 12:35 | E14: ="№6" -> №6 | F14: ="АТ 4021" -> АТ 4021 | G14: ="СВ 33-16 ЕО" -> СВ 33-16 ЕО | J14: =IF(A14="","",A14&"|"&B14) -> 1 пров. Межовий|1,2 5,8 | K14: =IFERROR(IF(D14="","",IF(D14="×",9.99,TIMEVALUE(D14))),9.99) -> 0.52430556 | L14: =IF($A14="","",IF(COUNTIFS($J$4:$J14,$J14,$E$4:$E14,$E14)=1,$E14,"")) -> №6 | M14: =IF($A14="","",IF(COUNTIFS($J$4:$J14,$J14,$F$4:$F14,$F14)=1,$F14,"")) -> АТ 4021
A15: =IFERROR(М5_МАЗ4381_0592!B175,"") -> 1 пров. Оранжерейний | B15: =IFERROR(IF(М5_МАЗ4381_0592!C175="","",TEXT(М5_МАЗ4381_0592!C175,"General")),"") | C15: ="П'ятниця" -> П'ятниця | D15: =IFERROR(TEXT(М5_МАЗ4381_0592!D175,"h:mm"),"") -> 10:25 | E15: ="№5" -> №5 | F15: ="МАЗ 4381" -> МАЗ 4381 | G15: ="СВ 81-71 ВК" -> СВ 81-71 ВК | J15: =IF(A15="","",A15&"|"&B15) -> 1 пров. Оранжерейний| | K15: =IFERROR(IF(D15="","",IF(D15="×",9.99,TIMEVALUE(D15))),9.99) -> 0.43402778 | L15: =IF($A15="","",IF(COUNTIFS($J$4:$J15,$J15,$E$4:$E15,$E15)=1,$E15,"")) -> №5 | M15: =IF($A15="","",IF(COUNTIFS($J$4:$J15,$J15,$F$4:$F15,$F15)=1,$F15,"")) -> МАЗ 4381
A16: =IFERROR(М5_МАЗ4381_0592!B16,"") -> 1 пров. П. Комуни | B16: =IFERROR(IF(М5_МАЗ4381_0592!C16="","",TEXT(М5_МАЗ4381_0592!C16,"General")),"") | C16: ="Понеділок" -> Понеділок | D16: =IFERROR(TEXT(М5_МАЗ4381_0592!D16,"h:mm"),"") -> 8:50 | E16: ="№5" -> №5 | F16: ="МАЗ 4381" -> МАЗ 4381 | G16: ="СВ 81-71 ВК" -> СВ 81-71 ВК | J16: =IF(A16="","",A16&"|"&B16) -> 1 пров. П. Комуни| | K16: =IFERROR(IF(D16="","",IF(D16="×",9.99,TIMEVALUE(D16))),9.99) -> 0.36805556 | L16: =IF($A16="","",IF(COUNTIFS($J$4:$J16,$J16,$E$4:$E16,$E16)=1,$E16,"")) -> №5 | M16: =IF($A16="","",IF(COUNTIFS($J$4:$J16,$J16,$F$4:$F16,$F16)=1,$F16,"")) -> МАЗ 4381
A17: =IFERROR(М6_АТ4021_0586!B108,"") -> 1 пров. Педагогічний | B17: =IFERROR(IF(М6_АТ4021_0586!C108="","",TEXT(М6_АТ4021_0586!C108,"General")),"") -> 9,11 6,3 | C17: ="Середа" -> Середа | D17: =IFERROR(TEXT(М6_АТ4021_0586!D108,"h:mm"),"") -> 15:30 | E17: ="№6" -> №6 | F17: ="АТ 4021" -> АТ 4021 | G17: ="СВ 33-16 ЕО" -> СВ 33-16 ЕО | J17: =IF(A17="","",A17&"|"&B17) -> 1 пров. Педагогічний|9,11 6,3 | K17: =IFERROR(IF(D17="","",IF(D17="×",9.99,TIMEVALUE(D17))),9.99) -> 0.64583333 | L17: =IF($A17="","",IF(COUNTIFS($J$4:$J17,$J17,$E$4:$E17,$E17)=1,$E17,"")) -> №6 | M17: =IF($A17="","",IF(COUNTIFS($J$4:$J17,$J17,$F$4:$F17,$F17)=1,$F17,"")) -> АТ 4021
A18: =IFERROR(М6_АТ4021_0586!B16,"") -> 1 пров. Пирогівський | B18: =IFERROR(IF(М6_АТ4021_0586!C16="","",TEXT(М6_АТ4021_0586!C16,"General")),"") -> 30,24 15,2 | C18: ="Понеділок" -> Понеділок | D18: =IFERROR(TEXT(М6_АТ4021_0586!D16,"h:mm"),"") -> 9:00 | E18: ="№6" -> №6 | F18: ="АТ 4021" -> АТ 4021 | G18: ="СВ 33-16 ЕО" -> СВ 33-16 ЕО | J18: =IF(A18="","",A18&"|"&B18) -> 1 пров. Пирогівський|30,24 15,2 | K18: =IFERROR(IF(D18="","",IF(D18="×",9.99,TIMEVALUE(D18))),9.99) -> 0.375 | L18: =IF($A18="","",IF(COUNTIFS($J$4:$J18,$J18,$E$4:$E18,$E18)=1,$E18,"")) -> №6 | M18: =IF($A18="","",IF(COUNTIFS($J$4:$J18,$J18,$F$4:$F18,$F18)=1,$F18,"")) -> АТ 4021
A19: =IFERROR(М5_МАЗ4381_0592!B21,"") -> 1 пров. Південний | B19: =IFERROR(IF(М5_МАЗ4381_0592!C21="","",TEXT(М5_МАЗ4381_0592!C21,"General")),"") | C19: ="Понеділок" -> Понеділок | D19: =IFERROR(TEXT(М5_МАЗ4381_0592!D21,"h:mm"),"") -> 10:10 | E19: ="№5" -> №5 | F19: ="МАЗ 4381" -> МАЗ 4381 | G19: ="СВ 81-71 ВК" -> СВ 81-71 ВК | J19: =IF(A19="","",A19&"|"&B19) -> 1 пров. Південний| | K19: =IFERROR(IF(D19="","",IF(D19="×",9.99,TIMEVALUE(D19))),9.99) -> 0.42361111 | L19: =IF($A19="","",IF(COUNTIFS($J$4:$J19,$J19,$E$4:$E19,$E19)=1,$E19,"")) -> №5 | M19: =IF($A19="","",IF(COUNTIFS($J$4:$J19,$J19,$F$4:$F19,$F19)=1,$F19,"")) -> МАЗ 4381
A20: =IFERROR(М5_МАЗ4381_0592!B36,"") -> 1 пров. Скоропадського | B20: =IFERROR(IF(М5_МАЗ4381_0592!C36="","",TEXT(М5_МАЗ4381_0592!C36,"General")),"") | C20: ="Понеділок" -> Понеділок | D20: =IFERROR(TEXT(М5_МАЗ4381_0592!D36,"h:mm"),"") -> 14:40 | E20: ="№5" -> №5 | F20: ="МАЗ 4381" -> МАЗ 4381 | G20: ="СВ 81-71 ВК" -> СВ 81-71 ВК | J20: =IF(A20="","",A20&"|"&B20) -> 1 пров. Скоропадського| | K20: =IFERROR(IF(D20="","",IF(D20="×",9.99,TIMEVALUE(D20))),9.99) -> 0.61111111 | L20: =IF($A20="","",IF(COUNTIFS($J$4:$J20,$J20,$E$4:$E20,$E20)=1,$E20,"")) -> №5 | M20: =IF($A20="","",IF(COUNTIFS($J$4:$J20,$J20,$F$4:$F20,$F20)=1,$F20,"")) -> МАЗ 4381
A21: =IFERROR(М5_МАЗ4381_0592!B194,"") -> 1 пров. Східний | B21: =IFERROR(IF(М5_МАЗ4381_0592!C194="","",TEXT(М5_МАЗ4381_0592!C194,"General")),"") | C21: ="П'ятниця" -> П'ятниця | D21: =IFERROR(TEXT(М5_МАЗ4381_0592!D194,"h:mm"),"") -> 14:30 | E21: ="№5" -> №5 | F21: ="МАЗ 4381" -> МАЗ 4381 | G21: ="СВ 81-71 ВК" -> СВ 81-71 ВК | J21: =IF(A21="","",A21&"|"&B21) -> 1 пров. Східний| | K21: =IFERROR(IF(D21="","",IF(D21="×",9.99,TIMEVALUE(D21))),9.99) -> 0.60416667 | L21: =IF($A21="","",IF(COUNTIFS($J$4:$J21,$J21,$E$4:$E21,$E21)=1,$E21,"")) -> №5 | M21: =IF($A21="","",IF(COUNTIFS($J$4:$J21,$J21,$F$4:$F21,$F21)=1,$F21,"")) -> МАЗ 4381
A22: =IFERROR(М6_АТ4021_0586!B35,"") -> 1 пров. Удайський | B22: =IFERROR(IF(М6_АТ4021_0586!C35="","",TEXT(М6_АТ4021_0586!C35,"General")),"") -> 23,33 15,5 | C22: ="Понеділок" -> Понеділок | D22: =IFERROR(TEXT(М6_АТ4021_0586!D35,"h:mm"),"") -> 15:00 | E22: ="№6" -> №6 | F22: ="АТ 4021" -> АТ 4021 | G22: ="СВ 33-16 ЕО" -> СВ 33-16 ЕО | J22: =IF(A22="","",A22&"|"&B22) -> 1 пров. Удайський|23,33 15,5 | K22: =IFERROR(IF(D22="","",IF(D22="×",9.99,TIMEVALUE(D22))),9.99) -> 0.625 | L22: =IF($A22="","",IF(COUNTIFS($J$4:$J22,$J22,$E$4:$E22,$E22)=1,$E22,"")) -> №6 | M22: =IF($A22="","",IF(COUNTIFS($J$4:$J22,$J22,$F$4:$F22,$F22)=1,$F22,"")) -> АТ 4021
A23: =IFERROR(М6_АТ4021_0586!B66,"") -> 1,2 в'їзд Шарапівський | B23: =IFERROR(IF(М6_АТ4021_0586!C66="","",TEXT(М6_АТ4021_0586!C66,"General")),"") -> 1,2 6,7 | C23: ="Вівторок" -> Вівторок | D23: =IFERROR(TEXT(М6_АТ4021_0586!D66,"h:mm"),"") -> 14:30 | E23: ="№6" -> №6 | F23: ="АТ 4021" -> АТ 4021 | G23: ="СВ 33-16 ЕО" -> СВ 33-16 ЕО | J23: =IF(A23="","",A23&"|"&B23) -> 1,2 в'їзд Шарапівський|1,2 6,7 | K23: =IFERROR(IF(D23="","",IF(D23="×",9.99,TIMEVALUE(D23))),9.99) -> 0.60416667 | L23: =IF($A23="","",IF(COUNTIFS($J$4:$J23,$J23,$E$4:$E23,$E23)=1,$E23,"")) -> №6 | M23: =IF($A23="","",IF(COUNTIFS($J$4:$J23,$J23,$F$4:$F23,$F23)=1,$F23,"")) -> АТ 4021
A24: =IFERROR(М3_МАЗ4371_0587!B136,"") -> 2 в'їзд Василя Стуса | B24: =IFERROR(IF(М3_МАЗ4371_0587!C136="","",TEXT(М3_МАЗ4371_0587!C136,"General")),"") | C24: ="П'ятниця" -> П'ятниця | D24: =IFERROR(TEXT(М3_МАЗ4371_0587!D136,"h:mm"),"") -> 13:25 | E24: ="№3" -> №3 | F24: ="МАЗ-4371" -> МАЗ-4371 | G24: ="СВ 53-06 СА" -> СВ 53-06 СА | H24: =IFERROR(М3_МАЗ4371_0587!G136,"") -> 3 | J24: =IF(A24="","",A24&"|"&B24) -> 2 в'їзд Василя Стуса| | K24: =IFERROR(IF(D24="","",IF(D24="×",9.99,TIMEVALUE(D24))),9.99) -> 0.55902778 | L24: =IF($A24="","",IF(COUNTIFS($J$4:$J24,$J24,$E$4:$E24,$E24)=1,$E24,"")) -> №3 | M24: =IF($A24="","",IF(COUNTIFS($J$4:$J24,$J24,$F$4:$F24,$F24)=1,$F24,"")) -> МАЗ-4371
A25: =IFERROR(М5_МАЗ4381_0592!B185,"") -> 2 в'їзд Вишневий | B25: =IFERROR(IF(М5_МАЗ4381_0592!C185="","",TEXT(М5_МАЗ4381_0592!C185,"General")),"") | C25: ="П'ятниця" -> П'ятниця | D25: =IFERROR(TEXT(М5_МАЗ4381_0592!D185,"h:mm"),"") -> 12:35 | E25: ="№5" -> №5 | F25: ="МАЗ 4381" -> МАЗ 4381 | G25: ="СВ 81-71 ВК" -> СВ 81-71 ВК | J25: =IF(A25="","",A25&"|"&B25) -> 2 в'їзд Вишневий| | K25: =IFERROR(IF(D25="","",IF(D25="×",9.99,TIMEVALUE(D25))),9.99) -> 0.52430556 | L25: =IF($A25="","",IF(COUNTIFS($J$4:$J25,$J25,$E$4:$E25,$E25)=1,$E25,"")) -> №5 | M25: =IF($A25="","",IF(COUNTIFS($J$4:$J25,$J25,$F$4:$F25,$F25)=1,$F25,"")) -> МАЗ 4381
A26: =IFERROR(М6_АТ4021_0586!B138,"") -> 2 в'їзд Гоголя | B26: =IFERROR(IF(М6_АТ4021_0586!C138="","",TEXT(М6_АТ4021_0586!C138,"General")),"") -> 4,14 | C26: ="Четвер" -> Четвер | D26: =IFERROR(TEXT(М6_АТ4021_0586!D138,"h:mm"),"") -> 13:15 | E26: ="№6" -> №6 | F26: ="АТ 4021" -> АТ 4021 | G26: ="СВ 33-16 ЕО" -> СВ 33-16 ЕО | J26: =IF(A26="","",A26&"|"&B26) -> 2 в'їзд Гоголя|4,14 | K26: =IFERROR(IF(D26="","",IF(D26="×",9.99,TIMEVALUE(D26))),9.99) -> 0.55208333 | L26: =IF($A26="","",IF(COUNTIFS($J$4:$J26,$J26,$E$4:$E26,$E26)=1,$E26,"")) -> №6 | M26: =IF($A26="","",IF(COUNTIFS($J$4:$J26,$J26,$F$4:$F26,$F26)=1,$F26,"")) -> АТ 4021
A27: =IFERROR('М3-4_ГАЗ3309_0590'!B123,"") -> 2 в-д Небесної Сотні | B27: =IFERROR(IF('М3-4_ГАЗ3309_0590'!C123="","",TEXT('М3-4_ГАЗ3309_0590'!C123,"General")),"") -> НВК | C27: ="Понеділок" -> Понеділок | D27: =IFERROR(TEXT('М3-4_ГАЗ3309_0590'!D123,"h:mm"),"") -> 8:05 | E27: ="№3" -> №3 | F27: ="ГАЗ 3309" -> ГАЗ 3309 | G27: ="СВ 17-85 ВН" -> СВ 17-85 ВН | H27: =IFERROR('М3-4_ГАЗ3309_0590'!G123,"") -> 2 | J27: =IF(A27="","",A27&"|"&B27) -> 2 в-д Небесної Сотні|НВК | K27: =IFERROR(IF(D27="","",IF(D27="×",9.99,TIMEVALUE(D27))),9.99) -> 0.33680556 | L27: =IF($A27="","",IF(COUNTIFS($J$4:$J27,$J27,$E$4:$E27,$E27)=1,$E27,"")) -> №3 | M27: =IF($A27="","",IF(COUNTIFS($J$4:$J27,$J27,$F$4:$F27,$F27)=1,$F27,"")) -> ГАЗ 3309
A28: =IFERROR(М5_МАЗ4381_0592!B125,"") -> 2 пров. Європейський | B28: =IFERROR(IF(М5_МАЗ4381_0592!C125="","",TEXT(М5_МАЗ4381_0592!C125,"General")),"") | C28: ="Четвер" -> Четвер | D28: =IFERROR(TEXT(М5_МАЗ4381_0592!D125,"h:mm"),"") -> 8:25 | E28: ="№5" -> №5 | F28: ="МАЗ 4381" -> МАЗ 4381 | G28: ="СВ 81-71 ВК" -> СВ 81-71 ВК | J28: =IF(A28="","",A28&"|"&B28) -> 2 пров. Європейський| | K28: =IFERROR(IF(D28="","",IF(D28="×",9.99,TIMEVALUE(D28))),9.99) -> 0.35069444 | L28: =IF($A28="","",IF(COUNTIFS($J$4:$J28,$J28,$E$4:$E28,$E28)=1,$E28,"")) -> №5 | M28: =IF($A28="","",IF(COUNTIFS($J$4:$J28,$J28,$F$4:$F28,$F28)=1,$F28,"")) -> МАЗ 4381
A29: =IFERROR(М5_МАЗ4381_0592!B64,"") -> 2 пров. І. Сірка | B29: =IFERROR(IF(М5_МАЗ4381_0592!C64="","",TEXT(М5_МАЗ4381_0592!C64,"General")),"") | C29: ="Вівторок" -> Вівторок | D29: =IFERROR(TEXT(М5_МАЗ4381_0592!D64,"h:mm"),"") -> 12:30 | E29: ="№5" -> №5 | F29: ="МАЗ 4381" -> МАЗ 4381 | G29: ="СВ 81-71 ВК" -> СВ 81-71 ВК | J29: =IF(A29="","",A29&"|"&B29) -> 2 пров. І. Сірка| | K29: =IFERROR(IF(D29="","",IF(D29="×",9.99,TIMEVALUE(D29))),9.99) -> 0.52083333 | L29: =IF($A29="","",IF(COUNTIFS($J$4:$J29,$J29,$E$4:$E29,$E29)=1,$E29,"")) -> №5 | M29: =IF($A29="","",IF(COUNTIFS($J$4:$J29,$J29,$F$4:$F29,$F29)=1,$F29,"")) -> МАЗ 4381
A30: =IFERROR(М4_АТ4042ROD_0584!B58,"") -> 2 пров. Андріївський | B30: =IFERROR(IF(М4_АТ4042ROD_0584!C58="","",TEXT(М4_АТ4042ROD_0584!C58,"General")),"") -> Моноліт | C30: ="Вівторок" -> Вівторок | D30: =IFERROR(TEXT(М4_АТ4042ROD_0584!D58,"h:mm"),"") -> 14:40 | E30: ="№4" -> №4 | F30: ="АТ 40-42/ROD21003" -> АТ 40-42/ROD21003 | G30: ="СВ 33-15 ЕО" -> СВ 33-15 ЕО | H30: =IFERROR(М4_АТ4042ROD_0584!G58,"") -> 2 | J30: =IF(A30="","",A30&"|"&B30) -> 2 пров. Андріївський|Моноліт | K30: =IFERROR(IF(D30="","",IF(D30="×",9.99,TIMEVALUE(D30))),9.99) -> 0.61111111 | L30: =IF($A30="","",IF(COUNTIFS($J$4:$J30,$J30,$E$4:$E30,$E30)=1,$E30,"")) -> №4 | M30: =IF($A30="","",IF(COUNTIFS($J$4:$J30,$J30,$F$4:$F30,$F30)=1,$F30,"")) -> АТ 40-42/ROD21003
A31: =IFERROR(М4_АТ4042ROD_0584!B91,"") -> 2 пров. Андріївський | B31: =IFERROR(IF(М4_АТ4042ROD_0584!C91="","",TEXT(М4_АТ4042ROD_0584!C91,"General")),"") -> Моноліт | C31: ="Четвер" -> Четвер | D31: =IFERROR(TEXT(М4_АТ4042ROD_0584!D91,"h:mm"),"") -> 14:25 | E31: ="№4" -> №4 | F31: ="АТ 40-42/ROD21003" -> АТ 40-42/ROD21003 | G31: ="СВ 33-15 ЕО" -> СВ 33-15 ЕО | H31: =IFERROR(М4_АТ4042ROD_0584!G91,"") -> 1 | J31: =IF(A31="","",A31&"|"&B31) -> 2 пров. Андріївський|Моноліт | K31: =IFERROR(IF(D31="","",IF(D31="×",9.99,TIMEVALUE(D31))),9.99) -> 0.60069444 | L31: =IF($A31="","",IF(COUNTIFS($J$4:$J31,$J31,$E$4:$E31,$E31)=1,$E31,"")) | M31: =IF($A31="","",IF(COUNTIFS($J$4:$J31,$J31,$F$4:$F31,$F31)=1,$F31,""))
A32: =IFERROR(М5_МАЗ4381_0592!B142,"") -> 2 пров. В. Стуса | B32: =IFERROR(IF(М5_МАЗ4381_0592!C142="","",TEXT(М5_МАЗ4381_0592!C142,"General")),"") | C32: ="Четвер" -> Четвер | D32: =IFERROR(TEXT(М5_МАЗ4381_0592!D142,"h:mm"),"") -> 12:55 | E32: ="№5" -> №5 | F32: ="МАЗ 4381" -> МАЗ 4381 | G32: ="СВ 81-71 ВК" -> СВ 81-71 ВК | J32: =IF(A32="","",A32&"|"&B32) -> 2 пров. В. Стуса| | K32: =IFERROR(IF(D32="","",IF(D32="×",9.99,TIMEVALUE(D32))),9.99) -> 0.53819444 | L32: =IF($A32="","",IF(COUNTIFS($J$4:$J32,$J32,$E$4:$E32,$E32)=1,$E32,"")) -> №5 | M32: =IF($A32="","",IF(COUNTIFS($J$4:$J32,$J32,$F$4:$F32,$F32)=1,$F32,"")) -> МАЗ 4381
A33: =IFERROR(М5_МАЗ4381_0592!B158,"") -> 2 пров. В. Чорновола | B33: =IFERROR(IF(М5_МАЗ4381_0592!C158="","",TEXT(М5_МАЗ4381_0592!C158,"General")),"") | C33: ="П'ятниця" -> П'ятниця | D33: =IFERROR(TEXT(М5_МАЗ4381_0592!D158,"h:mm"),"") -> 7:00 | E33: ="№5" -> №5 | F33: ="МАЗ 4381" -> МАЗ 4381 | G33: ="СВ 81-71 ВК" -> СВ 81-71 ВК | J33: =IF(A33="","",A33&"|"&B33) -> 2 пров. В. Чорновола| | K33: =IFERROR(IF(D33="","",IF(D33="×",9.99,TIMEVALUE(D33))),9.99) -> 0.29166667 | L33: =IF($A33="","",IF(COUNTIFS($J$4:$J33,$J33,$E$4:$E33,$E33)=1,$E33,"")) -> №5 | M33: =IF($A33="","",IF(COUNTIFS($J$4:$J33,$J33,$F$4:$F33,$F33)=1,$F33,"")) -> МАЗ 4381
A34: =IFERROR(М6_АТ4021_0586!B164,"") -> 2 пров. Героїв Прилук | B34: =IFERROR(IF(М6_АТ4021_0586!C164="","",TEXT(М6_АТ4021_0586!C164,"General")),"") -> 4, Гаражі | C34: ="П'ятниця" -> П'ятниця | D34: =IFERROR(TEXT(М6_АТ4021_0586!D164,"h:mm"),"") -> 9:30 | E34: ="№6" -> №6 | F34: ="АТ 4021" -> АТ 4021 | G34: ="СВ 33-16 ЕО" -> СВ 33-16 ЕО | J34: =IF(A34="","",A34&"|"&B34) -> 2 пров. Героїв Прилук|4, Гаражі | K34: =IFERROR(IF(D34="","",IF(D34="×",9.99,TIMEVALUE(D34))),9.99) -> 0.39583333 | L34: =IF($A34="","",IF(COUNTIFS($J$4:$J34,$J34,$E$4:$E34,$E34)=1,$E34,"")) -> №6 | M34: =IF($A34="","",IF(COUNTIFS($J$4:$J34,$J34,$F$4:$F34,$F34)=1,$F34,"")) -> АТ 4021
A35: =IFERROR(М6_АТ4021_0586!B64,"") -> 2 пров. Героїв Чорнобиля | B35: =IFERROR(IF(М6_АТ4021_0586!C64="","",TEXT(М6_АТ4021_0586!C64,"General")),"") -> 27,20 7,2 | C35: ="Вівторок" -> Вівторок | D35: =IFERROR(TEXT(М6_АТ4021_0586!D64,"h:mm"),"") -> 13:45 | E35: ="№6" -> №6 | F35: ="АТ 4021" -> АТ 4021 | G35: ="СВ 33-16 ЕО" -> СВ 33-16 ЕО | J35: =IF(A35="","",A35&"|"&B35) -> 2 пров. Героїв Чорнобиля|27,20 7,2 | K35: =IFERROR(IF(D35="","",IF(D35="×",9.99,TIMEVALUE(D35))),9.99) -> 0.57291667 | L35: =IF($A35="","",IF(COUNTIFS($J$4:$J35,$J35,$E$4:$E35,$E35)=1,$E35,"")) -> №6 | M35: =IF($A35="","",IF(COUNTIFS($J$4:$J35,$J35,$F$4:$F35,$F35)=1,$F35,"")) -> АТ 4021
A36: =IFERROR(М5_МАЗ4381_0592!B13,"") -> 2 пров. Дослідний | B36: =IFERROR(IF(М5_МАЗ4381_0592!C13="","",TEXT(М5_МАЗ4381_0592!C13,"General")),"") | C36: ="Понеділок" -> Понеділок | D36: =IFERROR(TEXT(М5_МАЗ4381_0592!D13,"h:mm"),"") -> 8:15 | E36: ="№5" -> №5 | F36: ="МАЗ 4381" -> МАЗ 4381 | G36: ="СВ 81-71 ВК" -> СВ 81-71 ВК | J36: =IF(A36="","",A36&"|"&B36) -> 2 пров. Дослідний| | K36: =IFERROR(IF(D36="","",IF(D36="×",9.99,TIMEVALUE(D36))),9.99) -> 0.34375 | L36: =IF($A36="","",IF(COUNTIFS($J$4:$J36,$J36,$E$4:$E36,$E36)=1,$E36,"")) -> №5 | M36: =IF($A36="","",IF(COUNTIFS($J$4:$J36,$J36,$F$4:$F36,$F36)=1,$F36,"")) -> МАЗ 4381
A37: =IFERROR(М5_МАЗ4381_0592!B29,"") -> 2 пров. Зелений | B37: =IFERROR(IF(М5_МАЗ4381_0592!C29="","",TEXT(М5_МАЗ4381_0592!C29,"General")),"") | C37: ="Понеділок" -> Понеділок | D37: =IFERROR(TEXT(М5_МАЗ4381_0592!D29,"h:mm"),"") -> 12:40 | E37: ="№5" -> №5 | F37: ="МАЗ 4381" -> МАЗ 4381 | G37: ="СВ 81-71 ВК" -> СВ 81-71 ВК | J37: =IF(A37="","",A37&"|"&B37) -> 2 пров. Зелений| | K37: =IFERROR(IF(D37="","",IF(D37="×",9.99,TIMEVALUE(D37))),9.99) -> 0.52777778 | L37: =IF($A37="","",IF(COUNTIFS($J$4:$J37,$J37,$E$4:$E37,$E37)=1,$E37,"")) -> №5 | M37: =IF($A37="","",IF(COUNTIFS($J$4:$J37,$J37,$F$4:$F37,$F37)=1,$F37,"")) -> МАЗ 4381
A38: =IFERROR(М5_МАЗ4381_0592!B32,"") -> 2 пров. Змагання | B38: =IFERROR(IF(М5_МАЗ4381_0592!C32="","",TEXT(М5_МАЗ4381_0592!C32,"General")),"") | C38: ="Понеділок" -> Понеділок | D38: =IFERROR(TEXT(М5_МАЗ4381_0592!D32,"h:mm"),"") -> 13:30 | E38: ="№5" -> №5 | F38: ="МАЗ 4381" -> МАЗ 4381 | G38: ="СВ 81-71 ВК" -> СВ 81-71 ВК | J38: =IF(A38="","",A38&"|"&B38) -> 2 пров. Змагання| | K38: =IFERROR(IF(D38="","",IF(D38="×",9.99,TIMEVALUE(D38))),9.99) -> 0.5625 | L38: =IF($A38="","",IF(COUNTIFS($J$4:$J38,$J38,$E$4:$E38,$E38)=1,$E38,"")) -> №5 | M38: =IF($A38="","",IF(COUNTIFS($J$4:$J38,$J38,$F$4:$F38,$F38)=1,$F38,"")) -> МАЗ 4381
A39: =IFERROR(М6_АТ4021_0586!B28,"") -> 2 пров. Межовий | B39: =IFERROR(IF(М6_АТ4021_0586!C28="","",TEXT(М6_АТ4021_0586!C28,"General")),"") -> 3,4 | C39: ="Понеділок" -> Понеділок | D39: =IFERROR(TEXT(М6_АТ4021_0586!D28,"h:mm"),"") -> 12:15 | E39: ="№6" -> №6 | F39: ="АТ 4021" -> АТ 4021 | G39: ="СВ 33-16 ЕО" -> СВ 33-16 ЕО | J39: =IF(A39="","",A39&"|"&B39) -> 2 пров. Межовий|3,4 | K39: =IFERROR(IF(D39="","",IF(D39="×",9.99,TIMEVALUE(D39))),9.99) -> 0.51041667 | L39: =IF($A39="","",IF(COUNTIFS($J$4:$J39,$J39,$E$4:$E39,$E39)=1,$E39,"")) -> №6 | M39: =IF($A39="","",IF(COUNTIFS($J$4:$J39,$J39,$F$4:$F39,$F39)=1,$F39,"")) -> АТ 4021
A40: =IFERROR(М5_МАЗ4381_0592!B18,"") -> 2 пров. П. Комуни | B40: =IFERROR(IF(М5_МАЗ4381_0592!C18="","",TEXT(М5_МАЗ4381_0592!C18,"General")),"") | C40: ="Понеділок" -> Понеділок | D40: =IFERROR(TEXT(М5_МАЗ4381_0592!D18,"h:mm"),"") -> 9:15 | E40: ="№5" -> №5 | F40: ="МАЗ 4381" -> МАЗ 4381 | G40: ="СВ 81-71 ВК" -> СВ 81-71 ВК | J40: =IF(A40="","",A40&"|"&B40) -> 2 пров. П. Комуни| | K40: =IFERROR(IF(D40="","",IF(D40="×",9.99,TIMEVALUE(D40))),9.99) -> 0.38541667 | L40: =IF($A40="","",IF(COUNTIFS($J$4:$J40,$J40,$E$4:$E40,$E40)=1,$E40,"")) -> №5 | M40: =IF($A40="","",IF(COUNTIFS($J$4:$J40,$J40,$F$4:$F40,$F40)=1,$F40,"")) -> МАЗ 4381
A41: =IFERROR(М6_АТ4021_0586!B106,"") -> 2 пров. Педагогічний | B41: =IFERROR(IF(М6_АТ4021_0586!C106="","",TEXT(М6_АТ4021_0586!C106,"General")),"") -> 5,11 14,20 | C41: ="Середа" -> Середа | D41: =IFERROR(TEXT(М6_АТ4021_0586!D106,"h:mm"),"") -> 15:00 | E41: ="№6" -> №6 | F41: ="АТ 4021" -> АТ 4021 | G41: ="СВ 33-16 ЕО" -> СВ 33-16 ЕО | J41: =IF(A41="","",A41&"|"&B41) -> 2 пров. Педагогічний|5,11 14,20 | K41: =IFERROR(IF(D41="","",IF(D41="×",9.99,TIMEVALUE(D41))),9.99) -> 0.625 | L41: =IF($A41="","",IF(COUNTIFS($J$4:$J41,$J41,$E$4:$E41,$E41)=1,$E41,"")) -> №6 | M41: =IF($A41="","",IF(COUNTIFS($J$4:$J41,$J41,$F$4:$F41,$F41)=1,$F41,"")) -> АТ 4021
...

Sheet Зведена_по_адресах
A1: Зведена таблиця вивезення ТПВ — за адресами (час вивозу за днями тижня)
A2: Значення тягнуться формулами. Легенда: зелений — ТПВ; оранжевий «×» — ВГВ; червоний текст вулиці — 1 вивіз/тиждень; синя заливка адреси — є контейнерний майданчик (аркуш «Координати майданчиків»), координати взято звідти.
A4: Назва вулиці | B4: Будинок / об'єкт | C4: Понеділок | D4: Вівторок | E4: Середа | F4: Четвер | G4: П'ятниця | H4: Субота | I4: Неділя | J4: Вивозів/тиж. | K4: Маршрут(и) | L4: Автомобіль(і) | M4: Контейнери | O4: Ключ | P4: Номер для геокоду | Q4: Повна адреса для запиту | R4: Широта | S4: Довгота | T4: Майданчик (з аркуша «Координати»)
A5: =IF($O5="","",LEFT($O5,FIND("|",$O5)-1)) -> 1 в'їзд Вишневий | B5: =IF($O5="","",MID($O5,FIND("|",$O5)+1,999)) | C5: {=IF($O5="","",_xlfn.TEXTJOIN(", ",TRUE,IF(EXACT('Дані_зв''язок'!$J$4:$J$1012,$O5)*('Дані_зв''язок'!$C$4:$C$1012=C$4),'Дані_зв''язок'!$D$4:$D$1012,"")))} | D5: {=IF($O5="","",_xlfn.TEXTJOIN(", ",TRUE,IF(EXACT('Дані_зв''язок'!$J$4:$J$1012,$O5)*('Дані_зв''язок'!$C$4:$C$1012=D$4),'Дані_зв''язок'!$D$4:$D$1012,"")))} | E5: {=IF($O5="","",_xlfn.TEXTJOIN(", ",TRUE,IF(EXACT('Дані_зв''язок'!$J$4:$J$1012,$O5)*('Дані_зв''язок'!$C$4:$C$1012=E$4),'Дані_зв''язок'!$D$4:$D$1012,"")))} | F5: {=IF($O5="","",_xlfn.TEXTJOIN(", ",TRUE,IF(EXACT('Дані_зв''язок'!$J$4:$J$1012,$O5)*('Дані_зв''язок'!$C$4:$C$1012=F$4),'Дані_зв''язок'!$D$4:$D$1012,"")))} | G5: {=IF($O5="","",_xlfn.TEXTJOIN(", ",TRUE,IF(EXACT('Дані_зв''язок'!$J$4:$J$1012,$O5)*('Дані_зв''язок'!$C$4:$C$1012=G$4),'Дані_зв''язок'!$D$4:$D$1012,"")))} -> 13:00 | H5: {=IF($O5="","",_xlfn.TEXTJOIN(", ",TRUE,IF(EXACT('Дані_зв''язок'!$J$4:$J$1012,$O5)*('Дані_зв''язок'!$C$4:$C$1012=H$4),'Дані_зв''язок'!$D$4:$D$1012,"")))} | I5: {=IF($O5="","",_xlfn.TEXTJOIN(", ",TRUE,IF(EXACT('Дані_зв''язок'!$J$4:$J$1012,$O5)*('Дані_зв''язок'!$C$4:$C$1012=I$4),'Дані_зв''язок'!$D$4:$D$1012,"")))} | J5: {=IF($O5="","",COUNTIF(C5:I5,"?*")+SUMPRODUCT(LEN(C5:I5)-LEN(SUBSTITUTE(C5:I5,",",""))))} -> 1 | K5: {=IF($O5="","",_xlfn.TEXTJOIN(", ",TRUE,IF(EXACT('Дані_зв''язок'!$J$4:$J$1012,$O5),'Дані_зв''язок'!$L$4:$L$1012,"")))} -> №5 | L5: {=IF($O5="","",_xlfn.TEXTJOIN(", ",TRUE,IF(EXACT('Дані_зв''язок'!$J$4:$J$1012,$O5),'Дані_зв''язок'!$M$4:$M$1012,"")))} -> МАЗ 4381 | M5: {=IF($O5="","",IF(SUMPRODUCT(MAX(EXACT('Дані_зв''язок'!$J$4:$J$1012,$O5)*IFERROR('Дані_зв''язок'!$H$4:$H$1012,0)))=0,"",SUMPRODUCT(MAX(EXACT('Дані_зв''язок'!$J$4:$J$1012,$O5)*IFERROR('Дані_зв''язок'!$H$4:$H$1012,0)))))} | O5: 1 в'їзд Вишневий| | P5: {=IF($O5="","",IF($B5="","",IFERROR(IF(MIN(IFERROR(VALUE(TRIM(MID(SUBSTITUTE(SUBSTITUTE($B5,","," ")," ",REPT(" ",30)),{1;31;61;91;121;151;181},30))),""))=0,"",MIN(IFERROR(VALUE(TRIM(MID(SUBSTITUTE(SUBSTITUTE($B5,","," ")," ",REPT(" ",30)),{1;31;61;91;121;151;181},30))),""))),"")))} | Q5: =IF($O5="","","Прилуки, Чернігівська обл., "&$A5&IF($P5="","",", "&$P5)) -> Прилуки, Чернігівська обл., 1 в'їзд Вишневий | R5: 50.583804 | S5: 32.424890 | T5: =IF($O5="","",IFERROR(INDEX('Координати майданчиків'!$B$4:$B$64,MATCH($A5&IF($P5="","",", "&$P5),'Координати майданчиків'!$B$4:$B$64,0)),IFERROR(INDEX('Координати майданчиків'!$B$4:$B$64,MATCH($A5,'Координати майданчиків'!$B$4:$B$64,0)),"")))
A6: =IF($O6="","",LEFT($O6,FIND("|",$O6)-1)) -> 1 пров. Європейський | B6: =IF($O6="","",MID($O6,FIND("|",$O6)+1,999)) | C6: {=IF($O6="","",_xlfn.TEXTJOIN(", ",TRUE,IF(EXACT('Дані_зв''язок'!$J$4:$J$1012,$O6)*('Дані_зв''язок'!$C$4:$C$1012=C$4),'Дані_зв''язок'!$D$4:$D$1012,"")))} | D6: {=IF($O6="","",_xlfn.TEXTJOIN(", ",TRUE,IF(EXACT('Дані_зв''язок'!$J$4:$J$1012,$O6)*('Дані_зв''язок'!$C$4:$C$1012=D$4),'Дані_зв''язок'!$D$4:$D$1012,"")))} | E6: {=IF($O6="","",_xlfn.TEXTJOIN(", ",TRUE,IF(EXACT('Дані_зв''язок'!$J$4:$J$1012,$O6)*('Дані_зв''язок'!$C$4:$C$1012=E$4),'Дані_зв''язок'!$D$4:$D$1012,"")))} | F6: {=IF($O6="","",_xlfn.TEXTJOIN(", ",TRUE,IF(EXACT('Дані_зв''язок'!$J$4:$J$1012,$O6)*('Дані_зв''язок'!$C$4:$C$1012=F$4),'Дані_зв''язок'!$D$4:$D$1012,"")))} -> 9:00 | G6: {=IF($O6="","",_xlfn.TEXTJOIN(", ",TRUE,IF(EXACT('Дані_зв''язок'!$J$4:$J$1012,$O6)*('Дані_зв''язок'!$C$4:$C$1012=G$4),'Дані_зв''язок'!$D$4:$D$1012,"")))} | H6: {=IF($O6="","",_xlfn.TEXTJOIN(", ",TRUE,IF(EXACT('Дані_зв''язок'!$J$4:$J$1012,$O6)*('Дані_зв''язок'!$C$4:$C$1012=H$4),'Дані_зв''язок'!$D$4:$D$1012,"")))} | I6: {=IF($O6="","",_xlfn.TEXTJOIN(", ",TRUE,IF(EXACT('Дані_зв''язок'!$J$4:$J$1012,$O6)*('Дані_зв''язок'!$C$4:$C$1012=I$4),'Дані_зв''язок'!$D$4:$D$1012,"")))} | J6: {=IF($O6="","",COUNTIF(C6:I6,"?*")+SUMPRODUCT(LEN(C6:I6)-LEN(SUBSTITUTE(C6:I6,",",""))))} -> 1 | K6: {=IF($O6="","",_xlfn.TEXTJOIN(", ",TRUE,IF(EXACT('Дані_зв''язок'!$J$4:$J$1012,$O6),'Дані_зв''язок'!$L$4:$L$1012,"")))} -> №5 | L6: {=IF($O6="","",_xlfn.TEXTJOIN(", ",TRUE,IF(EXACT('Дані_зв''язок'!$J$4:$J$1012,$O6),'Дані_зв''язок'!$M$4:$M$1012,"")))} -> МАЗ 4381 | M6: {=IF($O6="","",IF(SUMPRODUCT(MAX(EXACT('Дані_зв''язок'!$J$4:$J$1012,$O6)*IFERROR('Дані_зв''язок'!$H$4:$H$1012,0)))=0,"",SUMPRODUCT(MAX(EXACT('Дані_зв''язок'!$J$4:$J$1012,$O6)*IFERROR('Дані_зв''язок'!$H$4:$H$1012,0)))))} | O6: 1 пров. Європейський| | P6: {=IF($O6="","",IF($B6="","",IFERROR(IF(MIN(IFERROR(VALUE(TRIM(MID(SUBSTITUTE(SUBSTITUTE($B6,","," ")," ",REPT(" ",30)),{1;31;61;91;121;151;181},30))),""))=0,"",MIN(IFERROR(VALUE(TRIM(MID(SUBSTITUTE(SUBSTITUTE($B6,","," ")," ",REPT(" ",30)),{1;31;61;91;121;151;181},30))),""))),"")))} | Q6: =IF($O6="","","Прилуки, Чернігівська обл., "&$A6&IF($P6="","",", "&$P6)) -> Прилуки, Чернігівська обл., 1 пров. Європейський | R6: =IF($O6="","",IFERROR(INDEX('Координати майданчиків'!$H$4:$H$64,MATCH($T6,'Координати майданчиків'!$B$4:$B$64,0)),IFERROR(IF(ABS(INDEX(Геокодування!$C$2:$C$361,MATCH($Q6,Геокодування!$B$2:$B$361,0))-50.5884)+ABS(INDEX(Геокодування!$D$2:$D$361,MATCH($Q6,Геокодування!$B$2:$B$361,0))-32.3876)>0.15,"",INDEX(Геокодування!$C$2:$C$361,MATCH($Q6,Геокодування!$B$2:$B$361,0))),IFERROR(IF(ABS(INDEX(Геокодування!$C$2:$C$361,MATCH("Прилуки, Чернігівська обл., "&$A6,Геокодування!$B$2:$B$361,0))-50.5884)+ABS(INDEX(Геокодування!$D$2:$D$361,MATCH("Прилуки, Чернігівська обл., "&$A6,Геокодування!$B$2:$B$361,0))-32.3876)>0.15,"",INDEX(Геокодування!$C$2:$C$361,MATCH("Прилуки, Чернігівська обл., "&$A6,Геокодування!$B$2:$B$361,0))),"")))) -> 50.593848 | S6: =IF($O6="","",IFERROR(INDEX('Координати майданчиків'!$I$4:$I$64,MATCH($T6,'Координати майданчиків'!$B$4:$B$64,0)),IFERROR(IF(ABS(INDEX(Геокодування!$C$2:$C$361,MATCH($Q6,Геокодування!$B$2:$B$361,0))-50.5884)+ABS(INDEX(Геокодування!$D$2:$D$361,MATCH($Q6,Геокодування!$B$2:$B$361,0))-32.3876)>0.15,"",INDEX(Геокодування!$D$2:$D$361,MATCH($Q6,Геокодування!$B$2:$B$361,0))),IFERROR(IF(ABS(INDEX(Геокодування!$C$2:$C$361,MATCH("Прилуки, Чернігівська обл., "&$A6,Геокодування!$B$2:$B$361,0))-50.5884)+ABS(INDEX(Геокодування!$D$2:$D$361,MATCH("Прилуки, Чернігівська обл., "&$A6,Геокодування!$B$2:$B$361,0))-32.3876)>0.15,"",INDEX(Геокодування!$D$2:$D$361,MATCH("Прилуки, Чернігівська обл., "&$A6,Геокодування!$B$2:$B$361,0))),"")))) -> 32.365535 | T6: =IF($O6="","",IFERROR(INDEX('Координати майданчиків'!$B$4:$B$64,MATCH($A6&IF($P6="","",", "&$P6),'Координати майданчиків'!$B$4:$B$64,0)),IFERROR(INDEX('Координати майданчиків'!$B$4:$B$64,MATCH($A6,'Координати майданчиків'!$B$4:$B$64,0)),"")))
A7: =IF($O7="","",LEFT($O7,FIND("|",$O7)-1)) -> 1 пров. І. Сірка | B7: =IF($O7="","",MID($O7,FIND("|",$O7)+1,999)) | C7: {=IF($O7="","",_xlfn.TEXTJOIN(", ",TRUE,IF(EXACT('Дані_зв''язок'!$J$4:$J$1012,$O7)*('Дані_зв''язок'!$C$4:$C$1012=C$4),'Дані_зв''язок'!$D$4:$D$1012,"")))} | D7: {=IF($O7="","",_xlfn.TEXTJOIN(", ",TRUE,IF(EXACT('Дані_зв''язок'!$J$4:$J$1012,$O7)*('Дані_зв''язок'!$C$4:$C$1012=D$4),'Дані_зв''язок'!$D$4:$D$1012,"")))} -> 12:20 | E7: {=IF($O7="","",_xlfn.TEXTJOIN(", ",TRUE,IF(EXACT('Дані_зв''язок'!$J$4:$J$1012,$O7)*('Дані_зв''язок'!$C$4:$C$1012=E$4),'Дані_зв''язок'!$D$4:$D$1012,"")))} | F7: {=IF($O7="","",_xlfn.TEXTJOIN(", ",TRUE,IF(EXACT('Дані_зв''язок'!$J$4:$J$1012,$O7)*('Дані_зв''язок'!$C$4:$C$1012=F$4),'Дані_зв''язок'!$D$4:$D$1012,"")))} | G7: {=IF($O7="","",_xlfn.TEXTJOIN(", ",TRUE,IF(EXACT('Дані_зв''язок'!$J$4:$J$1012,$O7)*('Дані_зв''язок'!$C$4:$C$1012=G$4),'Дані_зв''язок'!$D$4:$D$1012,"")))} | H7: {=IF($O7="","",_xlfn.TEXTJOIN(", ",TRUE,IF(EXACT('Дані_зв''язок'!$J$4:$J$1012,$O7)*('Дані_зв''язок'!$C$4:$C$1012=H$4),'Дані_зв''язок'!$D$4:$D$1012,"")))} | I7: {=IF($O7="","",_xlfn.TEXTJOIN(", ",TRUE,IF(EXACT('Дані_зв''язок'!$J$4:$J$1012,$O7)*('Дані_зв''язок'!$C$4:$C$1012=I$4),'Дані_зв''язок'!$D$4:$D$1012,"")))} | J7: {=IF($O7="","",COUNTIF(C7:I7,"?*")+SUMPRODUCT(LEN(C7:I7)-LEN(SUBSTITUTE(C7:I7,",",""))))} -> 1 | K7: {=IF($O7="","",_xlfn.TEXTJOIN(", ",TRUE,IF(EXACT('Дані_зв''язок'!$J$4:$J$1012,$O7),'Дані_зв''язок'!$L$4:$L$1012,"")))} -> №5 | L7: {=IF($O7="","",_xlfn.TEXTJOIN(", ",TRUE,IF(EXACT('Дані_зв''язок'!$J$4:$J$1012,$O7),'Дані_зв''язок'!$M$4:$M$1012,"")))} -> МАЗ 4381 | M7: {=IF($O7="","",IF(SUMPRODUCT(MAX(EXACT('Дані_зв''язок'!$J$4:$J$1012,$O7)*IFERROR('Дані_зв''язок'!$H$4:$H$1012,0)))=0,"",SUMPRODUCT(MAX(EXACT('Дані_зв''язок'!$J$4:$J$1012,$O7)*IFERROR('Дані_зв''язок'!$H$4:$H$1012,0)))))} | O7: 1 пров. І. Сірка| | P7: {=IF($O7="","",IF($B7="","",IFERROR(IF(MIN(IFERROR(VALUE(TRIM(MID(SUBSTITUTE(SUBSTITUTE($B7,","," ")," ",REPT(" ",30)),{1;31;61;91;121;151;181},30))),""))=0,"",MIN(IFERROR(VALUE(TRIM(MID(SUBSTITUTE(SUBSTITUTE($B7,","," ")," ",REPT(" ",30)),{1;31;61;91;121;151;181},30))),""))),"")))} | Q7: =IF($O7="","","Прилуки, Чернігівська обл., "&$A7&IF($P7="","",", "&$P7)) -> Прилуки, Чернігівська обл., 1 пров. І. Сірка | R7: =IF($O7="","",IFERROR(INDEX('Координати майданчиків'!$H$4:$H$64,MATCH($T7,'Координати майданчиків'!$B$4:$B$64,0)),IFERROR(IF(ABS(INDEX(Геокодування!$C$2:$C$361,MATCH($Q7,Геокодування!$B$2:$B$361,0))-50.5884)+ABS(INDEX(Геокодування!$D$2:$D$361,MATCH($Q7,Геокодування!$B$2:$B$361,0))-32.3876)>0.15,"",INDEX(Геокодування!$C$2:$C$361,MATCH($Q7,Геокодування!$B$2:$B$361,0))),IFERROR(IF(ABS(INDEX(Геокодування!$C$2:$C$361,MATCH("Прилуки, Чернігівська обл., "&$A7,Геокодування!$B$2:$B$361,0))-50.5884)+ABS(INDEX(Геокодування!$D$2:$D$361,MATCH("Прилуки, Чернігівська обл., "&$A7,Геокодування!$B$2:$B$361,0))-32.3876)>0.15,"",INDEX(Геокодування!$C$2:$C$361,MATCH("Прилуки, Чернігівська обл., "&$A7,Геокодування!$B$2:$B$361,0))),"")))) -> 50.6032 | S7: =IF($O7="","",IFERROR(INDEX('Координати майданчиків'!$I$4:$I$64,MATCH($T7,'Координати майданчиків'!$B$4:$B$64,0)),IFERROR(IF(ABS(INDEX(Геокодування!$C$2:$C$361,MATCH($Q7,Геокодування!$B$2:$B$361,0))-50.5884)+ABS(INDEX(Геокодування!$D$2:$D$361,MATCH($Q7,Геокодування!$B$2:$B$361,0))-32.3876)>0.15,"",INDEX(Геокодування!$D$2:$D$361,MATCH($Q7,Геокодування!$B$2:$B$361,0))),IFERROR(IF(ABS(INDEX(Геокодування!$C$2:$C$361,MATCH("Прилуки, Чернігівська обл., "&$A7,Геокодування!$B$2:$B$361,0))-50.5884)+ABS(INDEX(Геокодування!$D$2:$D$361,MATCH("Прилуки, Чернігівська обл., "&$A7,Геокодування!$B$2:$B$361,0))-32.3876)>0.15,"",INDEX(Геокодування!$D$2:$D$361,MATCH("Прилуки, Чернігівська обл., "&$A7,Геокодування!$B$2:$B$361,0))),"")))) -> 32.330293 | T7: =IF($O7="","",IFERROR(INDEX('Координати майданчиків'!$B$4:$B$64,MATCH($A7&IF($P7="","",", "&$P7),'Координати майданчиків'!$B$4:$B$64,0)),IFERROR(INDEX('Координати майданчиків'!$B$4:$B$64,MATCH($A7,'Координати майданчиків'!$B$4:$B$64,0)),"")))
A8: =IF($O8="","",LEFT($O8,FIND("|",$O8)-1)) -> 1 пров. Андріївський | B8: =IF($O8="","",MID($O8,FIND("|",$O8)+1,999)) | C8: {=IF($O8="","",_xlfn.TEXTJOIN(", ",TRUE,IF(EXACT('Дані_зв''язок'!$J$4:$J$1012,$O8)*('Дані_зв''язок'!$C$4:$C$1012=C$4),'Дані_зв''язок'!$D$4:$D$1012,"")))} | D8: {=IF($O8="","",_xlfn.TEXTJOIN(", ",TRUE,IF(EXACT('Дані_зв''язок'!$J$4:$J$1012,$O8)*('Дані_зв''язок'!$C$4:$C$1012=D$4),'Дані_зв''язок'!$D$4:$D$1012,"")))} | E8: {=IF($O8="","",_xlfn.TEXTJOIN(", ",TRUE,IF(EXACT('Дані_зв''язок'!$J$4:$J$1012,$O8)*('Дані_зв''язок'!$C$4:$C$1012=E$4),'Дані_зв''язок'!$D$4:$D$1012,"")))} -> 10:40 | F8: {=IF($O8="","",_xlfn.TEXTJOIN(", ",TRUE,IF(EXACT('Дані_зв''язок'!$J$4:$J$1012,$O8)*('Дані_зв''язок'!$C$4:$C$1012=F$4),'Дані_зв''язок'!$D$4:$D$1012,"")))} | G8: {=IF($O8="","",_xlfn.TEXTJOIN(", ",TRUE,IF(EXACT('Дані_зв''язок'!$J$4:$J$1012,$O8)*('Дані_зв''язок'!$C$4:$C$1012=G$4),'Дані_зв''язок'!$D$4:$D$1012,"")))} | H8: {=IF($O8="","",_xlfn.TEXTJOIN(", ",TRUE,IF(EXACT('Дані_зв''язок'!$J$4:$J$1012,$O8)*('Дані_зв''язок'!$C$4:$C$1012=H$4),'Дані_зв''язок'!$D$4:$D$1012,"")))} | I8: {=IF($O8="","",_xlfn.TEXTJOIN(", ",TRUE,IF(EXACT('Дані_зв''язок'!$J$4:$J$1012,$O8)*('Дані_зв''язок'!$C$4:$C$1012=I$4),'Дані_зв''язок'!$D$4:$D$1012,"")))} | J8: {=IF($O8="","",COUNTIF(C8:I8,"?*")+SUMPRODUCT(LEN(C8:I8)-LEN(SUBSTITUTE(C8:I8,",",""))))} -> 1 | K8: {=IF($O8="","",_xlfn.TEXTJOIN(", ",TRUE,IF(EXACT('Дані_зв''язок'!$J$4:$J$1012,$O8),'Дані_зв''язок'!$L$4:$L$1012,"")))} -> №5 | L8: {=IF($O8="","",_xlfn.TEXTJOIN(", ",TRUE,IF(EXACT('Дані_зв''язок'!$J$4:$J$1012,$O8),'Дані_зв''язок'!$M$4:$M$1012,"")))} -> МАЗ 4381 | M8: {=IF($O8="","",IF(SUMPRODUCT(MAX(EXACT('Дані_зв''язок'!$J$4:$J$1012,$O8)*IFERROR('Дані_зв''язок'!$H$4:$H$1012,0)))=0,"",SUMPRODUCT(MAX(EXACT('Дані_зв''язок'!$J$4:$J$1012,$O8)*IFERROR('Дані_зв''язок'!$H$4:$H$1012,0)))))} | O8: 1 пров. Андріївський| | P8: {=IF($O8="","",IF($B8="","",IFERROR(IF(MIN(IFERROR(VALUE(TRIM(MID(SUBSTITUTE(SUBSTITUTE($B8,","," ")," ",REPT(" ",30)),{1;31;61;91;121;151;181},30))),""))=0,"",MIN(IFERROR(VALUE(TRIM(MID(SUBSTITUTE(SUBSTITUTE($B8,","," ")," ",REPT(" ",30)),{1;31;61;91;121;151;181},30))),""))),"")))} | Q8: =IF($O8="","","Прилуки, Чернігівська обл., "&$A8&IF($P8="","",", "&$P8)) -> Прилуки, Чернігівська обл., 1 пров. Андріївський | R8: =IF($O8="","",IFERROR(INDEX('Координати майданчиків'!$H$4:$H$64,MATCH($T8,'Координати майданчиків'!$B$4:$B$64,0)),IFERROR(IF(ABS(INDEX(Геокодування!$C$2:$C$361,MATCH($Q8,Геокодування!$B$2:$B$361,0))-50.5884)+ABS(INDEX(Геокодування!$D$2:$D$361,MATCH($Q8,Геокодування!$B$2:$B$361,0))-32.3876)>0.15,"",INDEX(Геокодування!$C$2:$C$361,MATCH($Q8,Геокодування!$B$2:$B$361,0))),IFERROR(IF(ABS(INDEX(Геокодування!$C$2:$C$361,MATCH("Прилуки, Чернігівська обл., "&$A8,Геокодування!$B$2:$B$361,0))-50.5884)+ABS(INDEX(Геокодування!$D$2:$D$361,MATCH("Прилуки, Чернігівська обл., "&$A8,Геокодування!$B$2:$B$361,0))-32.3876)>0.15,"",INDEX(Геокодування!$C$2:$C$361,MATCH("Прилуки, Чернігівська обл., "&$A8,Геокодування!$B$2:$B$361,0))),"")))) -> 50.591387 | S8: =IF($O8="","",IFERROR(INDEX('Координати майданчиків'!$I$4:$I$64,MATCH($T8,'Координати майданчиків'!$B$4:$B$64,0)),IFERROR(IF(ABS(INDEX(Геокодування!$C$2:$C$361,MATCH($Q8,Геокодування!$B$2:$B$361,0))-50.5884)+ABS(INDEX(Геокодування!$D$2:$D$361,MATCH($Q8,Геокодування!$B$2:$B$361,0))-32.3876)>0.15,"",INDEX(Геокодування!$D$2:$D$361,MATCH($Q8,Геокодування!$B$2:$B$361,0))),IFERROR(IF(ABS(INDEX(Геокодування!$C$2:$C$361,MATCH("Прилуки, Чернігівська обл., "&$A8,Геокодування!$B$2:$B$361,0))-50.5884)+ABS(INDEX(Геокодування!$D$2:$D$361,MATCH("Прилуки, Чернігівська обл., "&$A8,Геокодування!$B$2:$B$361,0))-32.3876)>0.15,"",INDEX(Геокодування!$D$2:$D$361,MATCH("Прилуки, Чернігівська обл., "&$A8,Геокодування!$B$2:$B$361,0))),"")))) -> 32.370229 | T8: =IF($O8="","",IFERROR(INDEX('Координати майданчиків'!$B$4:$B$64,MATCH($A8&IF($P8="","",", "&$P8),'Координати майданчиків'!$B$4:$B$64,0)),IFERROR(INDEX('Координати майданчиків'!$B$4:$B$64,MATCH($A8,'Координати майданчиків'!$B$4:$B$64,0)),"")))
A9: =IF($O9="","",LEFT($O9,FIND("|",$O9)-1)) -> 1 пров. В. Стуса | B9: =IF($O9="","",MID($O9,FIND("|",$O9)+1,999)) | C9: {=IF($O9="","",_xlfn.TEXTJOIN(", ",TRUE,IF(EXACT('Дані_зв''язок'!$J$4:$J$1012,$O9)*('Дані_зв''язок'!$C$4:$C$1012=C$4),'Дані_зв''язок'!$D$4:$D$1012,"")))} | D9: {=IF($O9="","",_xlfn.TEXTJOIN(", ",TRUE,IF(EXACT('Дані_зв''язок'!$J$4:$J$1012,$O9)*('Дані_зв''язок'!$C$4:$C$1012=D$4),'Дані_зв''язок'!$D$4:$D$1012,"")))} | E9: {=IF($O9="","",_xlfn.TEXTJOIN(", ",TRUE,IF(EXACT('Дані_зв''язок'!$J$4:$J$1012,$O9)*('Дані_зв''язок'!$C$4:$C$1012=E$4),'Дані_зв''язок'!$D$4:$D$1012,"")))} | F9: {=IF($O9="","",_xlfn.TEXTJOIN(", ",TRUE,IF(EXACT('Дані_зв''язок'!$J$4:$J$1012,$O9)*('Дані_зв''язок'!$C$4:$C$1012=F$4),'Дані_зв''язок'!$D$4:$D$1012,"")))} -> 12:45 | G9: {=IF($O9="","",_xlfn.TEXTJOIN(", ",TRUE,IF(EXACT('Дані_зв''язок'!$J$4:$J$1012,$O9)*('Дані_зв''язок'!$C$4:$C$1012=G$4),'Дані_зв''язок'!$D$4:$D$1012,"")))} | H9: {=IF($O9="","",_xlfn.TEXTJOIN(", ",TRUE,IF(EXACT('Дані_зв''язок'!$J$4:$J$1012,$O9)*('Дані_зв''язок'!$C$4:$C$1012=H$4),'Дані_зв''язок'!$D$4:$D$1012,"")))} | I9: {=IF($O9="","",_xlfn.TEXTJOIN(", ",TRUE,IF(EXACT('Дані_зв''язок'!$J$4:$J$1012,$O9)*('Дані_зв''язок'!$C$4:$C$1012=I$4),'Дані_зв''язок'!$D$4:$D$1012,"")))} | J9: {=IF($O9="","",COUNTIF(C9:I9,"?*")+SUMPRODUCT(LEN(C9:I9)-LEN(SUBSTITUTE(C9:I9,",",""))))} -> 1 | K9: {=IF($O9="","",_xlfn.TEXTJOIN(", ",TRUE,IF(EXACT('Дані_зв''язок'!$J$4:$J$1012,$O9),'Дані_зв''язок'!$L$4:$L$1012,"")))} -> №5 | L9: {=IF($O9="","",_xlfn.TEXTJOIN(", ",TRUE,IF(EXACT('Дані_зв''язок'!$J$4:$J$1012,$O9),'Дані_зв''язок'!$M$4:$M$1012,"")))} -> МАЗ 4381 | M9: {=IF($O9="","",IF(SUMPRODUCT(MAX(EXACT('Дані_зв''язок'!$J$4:$J$1012,$O9)*IFERROR('Дані_зв''язок'!$H$4:$H$1012,0)))=0,"",SUMPRODUCT(MAX(EXACT('Дані_зв''язок'!$J$4:$J$1012,$O9)*IFERROR('Дані_зв''язок'!$H$4:$H$1012,0)))))} | O9: 1 пров. В. Стуса| | P9: {=IF($O9="","",IF($B9="","",IFERROR(IF(MIN(IFERROR(VALUE(TRIM(MID(SUBSTITUTE(SUBSTITUTE($B9,","," ")," ",REPT(" ",30)),{1;31;61;91;121;151;181},30))),""))=0,"",MIN(IFERROR(VALUE(TRIM(MID(SUBSTITUTE(SUBSTITUTE($B9,","," ")," ",REPT(" ",30)),{1;31;61;91;121;151;181},30))),""))),"")))} | Q9: =IF($O9="","","Прилуки, Чернігівська обл., "&$A9&IF($P9="","",", "&$P9)) -> Прилуки, Чернігівська обл., 1 пров. В. Стуса | R9: =IF($O9="","",IFERROR(INDEX('Координати майданчиків'!$H$4:$H$64,MATCH($T9,'Координати майданчиків'!$B$4:$B$64,0)),IFERROR(IF(ABS(INDEX(Геокодування!$C$2:$C$361,MATCH($Q9,Геокодування!$B$2:$B$361,0))-50.5884)+ABS(INDEX(Геокодування!$D$2:$D$361,MATCH($Q9,Геокодування!$B$2:$B$361,0))-32.3876)>0.15,"",INDEX(Геокодування!$C$2:$C$361,MATCH($Q9,Геокодування!$B$2:$B$361,0))),IFERROR(IF(ABS(INDEX(Геокодування!$C$2:$C$361,MATCH("Прилуки, Чернігівська обл., "&$A9,Геокодування!$B$2:$B$361,0))-50.5884)+ABS(INDEX(Геокодування!$D$2:$D$361,MATCH("Прилуки, Чернігівська обл., "&$A9,Геокодування!$B$2:$B$361,0))-32.3876)>0.15,"",INDEX(Геокодування!$C$2:$C$361,MATCH("Прилуки, Чернігівська обл., "&$A9,Геокодування!$B$2:$B$361,0))),"")))) -> 50.579769 | S9: =IF($O9="","",IFERROR(INDEX('Координати майданчиків'!$I$4:$I$64,MATCH($T9,'Координати майданчиків'!$B$4:$B$64,0)),IFERROR(IF(ABS(INDEX(Геокодування!$C$2:$C$361,MATCH($Q9,Геокодування!$B$2:$B$361,0))-50.5884)+ABS(INDEX(Геокодування!$D$2:$D$361,MATCH($Q9,Геокодування!$B$2:$B$361,0))-32.3876)>0.15,"",INDEX(Геокодування!$D$2:$D$361,MATCH($Q9,Геокодування!$B$2:$B$361,0))),IFERROR(IF(ABS(INDEX(Геокодування!$C$2:$C$361,MATCH("Прилуки, Чернігівська обл., "&$A9,Геокодування!$B$2:$B$361,0))-50.5884)+ABS(INDEX(Геокодування!$D$2:$D$361,MATCH("Прилуки, Чернігівська обл., "&$A9,Геокодування!$B$2:$B$361,0))-32.3876)>0.15,"",INDEX(Геокодування!$D$2:$D$361,MATCH("Прилуки, Чернігівська обл., "&$A9,Геокодування!$B$2:$B$361,0))),"")))) -> 32.420833 | T9: =IF($O9="","",IFERROR(INDEX('Координати майданчиків'!$B$4:$B$64,MATCH($A9&IF($P9="","",", "&$P9),'Координати майданчиків'!$B$4:$B$64,0)),IFERROR(INDEX('Координати майданчиків'!$B$4:$B$64,MATCH($A9,'Координати майданчиків'!$B$4:$B$64,0)),"")))
A10: =IF($O10="","",LEFT($O10,FIND("|",$O10)-1)) -> 1 пров. Героїв Чорнобиля | B10: =IF($O10="","",MID($O10,FIND("|",$O10)+1,999)) -> 2,10 24 | C10: {=IF($O10="","",_xlfn.TEXTJOIN(", ",TRUE,IF(EXACT('Дані_зв''язок'!$J$4:$J$1012,$O10)*('Дані_зв''язок'!$C$4:$C$1012=C$4),'Дані_зв''язок'!$D$4:$D$1012,"")))} | D10: {=IF($O10="","",_xlfn.TEXTJOIN(", ",TRUE,IF(EXACT('Дані_зв''язок'!$J$4:$J$1012,$O10)*('Дані_зв''язок'!$C$4:$C$1012=D$4),'Дані_зв''язок'!$D$4:$D$1012,"")))} | E10: {=IF($O10="","",_xlfn.TEXTJOIN(", ",TRUE,IF(EXACT('Дані_зв''язок'!$J$4:$J$1012,$O10)*('Дані_зв''язок'!$C$4:$C$1012=E$4),'Дані_зв''язок'!$D$4:$D$1012,"")))} | F10: {=IF($O10="","",_xlfn.TEXTJOIN(", ",TRUE,IF(EXACT('Дані_зв''язок'!$J$4:$J$1012,$O10)*('Дані_зв''язок'!$C$4:$C$1012=F$4),'Дані_зв''язок'!$D$4:$D$1012,"")))} | G10: {=IF($O10="","",_xlfn.TEXTJOIN(", ",TRUE,IF(EXACT('Дані_зв''язок'!$J$4:$J$1012,$O10)*('Дані_зв''язок'!$C$4:$C$1012=G$4),'Дані_зв''язок'!$D$4:$D$1012,"")))} -> 10:45 | H10: {=IF($O10="","",_xlfn.TEXTJOIN(", ",TRUE,IF(EXACT('Дані_зв''язок'!$J$4:$J$1012,$O10)*('Дані_зв''язок'!$C$4:$C$1012=H$4),'Дані_зв''язок'!$D$4:$D$1012,"")))} | I10: {=IF($O10="","",_xlfn.TEXTJOIN(", ",TRUE,IF(EXACT('Дані_зв''язок'!$J$4:$J$1012,$O10)*('Дані_зв''язок'!$C$4:$C$1012=I$4),'Дані_зв''язок'!$D$4:$D$1012,"")))} | J10: {=IF($O10="","",COUNTIF(C10:I10,"?*")+SUMPRODUCT(LEN(C10:I10)-LEN(SUBSTITUTE(C10:I10,",",""))))} -> 1 | K10: {=IF($O10="","",_xlfn.TEXTJOIN(", ",TRUE,IF(EXACT('Дані_зв''язок'!$J$4:$J$1012,$O10),'Дані_зв''язок'!$L$4:$L$1012,"")))} -> №6 | L10: {=IF($O10="","",_xlfn.TEXTJOIN(", ",TRUE,IF(EXACT('Дані_зв''язок'!$J$4:$J$1012,$O10),'Дані_зв''язок'!$M$4:$M$1012,"")))} -> АТ 4021 | M10: {=IF($O10="","",IF(SUMPRODUCT(MAX(EXACT('Дані_зв''язок'!$J$4:$J$1012,$O10)*IFERROR('Дані_зв''язок'!$H$4:$H$1012,0)))=0,"",SUMPRODUCT(MAX(EXACT('Дані_зв''язок'!$J$4:$J$1012,$O10)*IFERROR('Дані_зв''язок'!$H$4:$H$1012,0)))))} | O10: 1 пров. Героїв Чорнобиля|2,10 24 | P10: {=IF($O10="","",IF($B10="","",IFERROR(IF(MIN(IFERROR(VALUE(TRIM(MID(SUBSTITUTE(SUBSTITUTE($B10,","," ")," ",REPT(" ",30)),{1;31;61;91;121;151;181},30))),""))=0,"",MIN(IFERROR(VALUE(TRIM(MID(SUBSTITUTE(SUBSTITUTE($B10,","," ")," ",REPT(" ",30)),{1;31;61;91;121;151;181},30))),""))),"")))} -> 2 | Q10: =IF($O10="","","Прилуки, Чернігівська обл., "&$A10&IF($P10="","",", "&$P10)) -> Прилуки, Чернігівська обл., 1 пров. Героїв Чорнобиля, 2 | R10: =IF($O10="","",IFERROR(INDEX('Координати майданчиків'!$H$4:$H$64,MATCH($T10,'Координати майданчиків'!$B$4:$B$64,0)),IFERROR(IF(ABS(INDEX(Геокодування!$C$2:$C$361,MATCH($Q10,Геокодування!$B$2:$B$361,0))-50.5884)+ABS(INDEX(Геокодування!$D$2:$D$361,MATCH($Q10,Геокодування!$B$2:$B$361,0))-32.3876)>0.15,"",INDEX(Геокодування!$C$2:$C$361,MATCH($Q10,Геокодування!$B$2:$B$361,0))),IFERROR(IF(ABS(INDEX(Геокодування!$C$2:$C$361,MATCH("Прилуки, Чернігівська обл., "&$A10,Геокодування!$B$2:$B$361,0))-50.5884)+ABS(INDEX(Геокодування!$D$2:$D$361,MATCH("Прилуки, Чернігівська обл., "&$A10,Геокодування!$B$2:$B$361,0))-32.3876)>0.15,"",INDEX(Геокодування!$C$2:$C$361,MATCH("Прилуки, Чернігівська обл., "&$A10,Геокодування!$B$2:$B$361,0))),"")))) -> 50.594935 | S10: =IF($O10="","",IFERROR(INDEX('Координати майданчиків'!$I$4:$I$64,MATCH($T10,'Координати майданчиків'!$B$4:$B$64,0)),IFERROR(IF(ABS(INDEX(Геокодування!$C$2:$C$361,MATCH($Q10,Геокодування!$B$2:$B$361,0))-50.5884)+ABS(INDEX(Геокодування!$D$2:$D$361,MATCH($Q10,Геокодування!$B$2:$B$361,0))-32.3876)>0.15,"",INDEX(Геокодування!$D$2:$D$361,MATCH($Q10,Геокодування!$B$2:$B$361,0))),IFERROR(IF(ABS(INDEX(Геокодування!$C$2:$C$361,MATCH("Прилуки, Чернігівська обл., "&$A10,Геокодування!$B$2:$B$361,0))-50.5884)+ABS(INDEX(Геокодування!$D$2:$D$361,MATCH("Прилуки, Чернігівська обл., "&$A10,Геокодування!$B$2:$B$361,0))-32.3876)>0.15,"",INDEX(Геокодування!$D$2:$D$361,MATCH("Прилуки, Чернігівська обл., "&$A10,Геокодування!$B$2:$B$361,0))),"")))) -> 32.415867 | T10: =IF($O10="","",IFERROR(INDEX('Координати майданчиків'!$B$4:$B$64,MATCH($A10&IF($P10="","",", "&$P10),'Координати майданчиків'!$B$4:$B$64,0)),IFERROR(INDEX('Координати майданчиків'!$B$4:$B$64,MATCH($A10,'Координати майданчиків'!$B$4:$B$64,0)),"")))
A11: =IF($O11="","",LEFT($O11,FIND("|",$O11)-1)) -> 1 пров. Замостянський | B11: =IF($O11="","",MID($O11,FIND("|",$O11)+1,999)) -> 36,42 54 | C11: {=IF($O11="","",_xlfn.TEXTJOIN(", ",TRUE,IF(EXACT('Дані_зв''язок'!$J$4:$J$1012,$O11)*('Дані_зв''язок'!$C$4:$C$1012=C$4),'Дані_зв''язок'!$D$4:$D$1012,"")))} | D11: {=IF($O11="","",_xlfn.TEXTJOIN(", ",TRUE,IF(EXACT('Дані_зв''язок'!$J$4:$J$1012,$O11)*('Дані_зв''язок'!$C$4:$C$1012=D$4),'Дані_зв''язок'!$D$4:$D$1012,"")))} | E11: {=IF($O11="","",_xlfn.TEXTJOIN(", ",TRUE,IF(EXACT('Дані_зв''язок'!$J$4:$J$1012,$O11)*('Дані_зв''язок'!$C$4:$C$1012=E$4),'Дані_зв''язок'!$D$4:$D$1012,"")))} | F11: {=IF($O11="","",_xlfn.TEXTJOIN(", ",TRUE,IF(EXACT('Дані_зв''язок'!$J$4:$J$1012,$O11)*('Дані_зв''язок'!$C$4:$C$1012=F$4),'Дані_зв''язок'!$D$4:$D$1012,"")))} -> 9:55 | G11: {=IF($O11="","",_xlfn.TEXTJOIN(", ",TRUE,IF(EXACT('Дані_зв''язок'!$J$4:$J$1012,$O11)*('Дані_зв''язок'!$C$4:$C$1012=G$4),'Дані_зв''язок'!$D$4:$D$1012,"")))} | H11: {=IF($O11="","",_xlfn.TEXTJOIN(", ",TRUE,IF(EXACT('Дані_зв''язок'!$J$4:$J$1012,$O11)*('Дані_зв''язок'!$C$4:$C$1012=H$4),'Дані_зв''язок'!$D$4:$D$1012,"")))} | I11: {=IF($O11="","",_xlfn.TEXTJOIN(", ",TRUE,IF(EXACT('Дані_зв''язок'!$J$4:$J$1012,$O11)*('Дані_зв''язок'!$C$4:$C$1012=I$4),'Дані_зв''язок'!$D$4:$D$1012,"")))} | J11: {=IF($O11="","",COUNTIF(C11:I11,"?*")+SUMPRODUCT(LEN(C11:I11)-LEN(SUBSTITUTE(C11:I11,",",""))))} -> 1 | K11: {=IF($O11="","",_xlfn.TEXTJOIN(", ",TRUE,IF(EXACT('Дані_зв''язок'!$J$4:$J$1012,$O11),'Дані_зв''язок'!$L$4:$L$1012,"")))} -> №6 | L11: {=IF($O11="","",_xlfn.TEXTJOIN(", ",TRUE,IF(EXACT('Дані_зв''язок'!$J$4:$J$1012,$O11),'Дані_зв''язок'!$M$4:$M$1012,"")))} -> АТ 4021 | M11: {=IF($O11="","",IF(SUMPRODUCT(MAX(EXACT('Дані_зв''язок'!$J$4:$J$1012,$O11)*IFERROR('Дані_зв''язок'!$H$4:$H$1012,0)))=0,"",SUMPRODUCT(MAX(EXACT('Дані_зв''язок'!$J$4:$J$1012,$O11)*IFERROR('Дані_зв''язок'!$H$4:$H$1012,0)))))} | O11: 1 пров. Замостянський|36,42 54 | P11: {=IF($O11="","",IF($B11="","",IFERROR(IF(MIN(IFERROR(VALUE(TRIM(MID(SUBSTITUTE(SUBSTITUTE($B11,","," ")," ",REPT(" ",30)),{1;31;61;91;121;151;181},30))),""))=0,"",MIN(IFERROR(VALUE(TRIM(MID(SUBSTITUTE(SUBSTITUTE($B11,","," ")," ",REPT(" ",30)),{1;31;61;91;121;151;181},30))),""))),"")))} -> 36 | Q11: =IF($O11="","","Прилуки, Чернігівська обл., "&$A11&IF($P11="","",", "&$P11)) -> Прилуки, Чернігівська обл., 1 пров. Замостянський, 36 | R11: =IF($O11="","",IFERROR(INDEX('Координати майданчиків'!$H$4:$H$64,MATCH($T11,'Координати майданчиків'!$B$4:$B$64,0)),IFERROR(IF(ABS(INDEX(Геокодування!$C$2:$C$361,MATCH($Q11,Геокодування!$B$2:$B$361,0))-50.5884)+ABS(INDEX(Геокодування!$D$2:$D$361,MATCH($Q11,Геокодування!$B$2:$B$361,0))-32.3876)>0.15,"",INDEX(Геокодування!$C$2:$C$361,MATCH($Q11,Геокодування!$B$2:$B$361,0))),IFERROR(IF(ABS(INDEX(Геокодування!$C$2:$C$361,MATCH("Прилуки, Чернігівська обл., "&$A11,Геокодування!$B$2:$B$361,0))-50.5884)+ABS(INDEX(Геокодування!$D$2:$D$361,MATCH("Прилуки, Чернігівська обл., "&$A11,Геокодування!$B$2:$B$361,0))-32.3876)>0.15,"",INDEX(Геокодування!$C$2:$C$361,MATCH("Прилуки, Чернігівська обл., "&$A11,Геокодування!$B$2:$B$361,0))),"")))) -> 50.61144 | S11: =IF($O11="","",IFERROR(INDEX('Координати майданчиків'!$I$4:$I$64,MATCH($T11,'Координати майданчиків'!$B$4:$B$64,0)),IFERROR(IF(ABS(INDEX(Геокодування!$C$2:$C$361,MATCH($Q11,Геокодування!$B$2:$B$361,0))-50.5884)+ABS(INDEX(Геокодування!$D$2:$D$361,MATCH($Q11,Геокодування!$B$2:$B$361,0))-32.3876)>0.15,"",INDEX(Геокодування!$D$2:$D$361,MATCH($Q11,Геокодування!$B$2:$B$361,0))),IFERROR(IF(ABS(INDEX(Геокодування!$C$2:$C$361,MATCH("Прилуки, Чернігівська обл., "&$A11,Геокодування!$B$2:$B$361,0))-50.5884)+ABS(INDEX(Геокодування!$D$2:$D$361,MATCH("Прилуки, Чернігівська обл., "&$A11,Геокодування!$B$2:$B$361,0))-32.3876)>0.15,"",INDEX(Геокодування!$D$2:$D$361,MATCH("Прилуки, Чернігівська обл., "&$A11,Геокодування!$B$2:$B$361,0))),"")))) -> 32.394473 | T11: =IF($O11="","",IFERROR(INDEX('Координати майданчиків'!$B$4:$B$64,MATCH($A11&IF($P11="","",", "&$P11),'Координати майданчиків'!$B$4:$B$64,0)),IFERROR(INDEX('Координати майданчиків'!$B$4:$B$64,MATCH($A11,'Координати майданчиків'!$B$4:$B$64,0)),"")))
